Workbook

Sheet 00_摘要
A1: 万物云2026年上半年财务数据库 | B1: 万物云2026年上半年财务数据库 | C1: 万物云2026年上半年财务数据库 | D1: 万物云2026年上半年财务数据库 | E1: 万物云2026年上半年财务数据库 | F1: 万物云2026年上半年财务数据库 | G1: 万物云2026年上半年财务数据库 | H1: 万物云2026年上半年财务数据库
A2: 截至2026年6月30日止六个月 | 未经审计 | 币种：人民币 | 报告金额默认单位：人民币千元 | B2: 截至2026年6月30日止六个月 | 未经审计 | 币种：人民币 | 报告金额默认单位：人民币千元 | C2: 截至2026年6月30日止六个月 | 未经审计 | 币种：人民币 | 报告金额默认单位：人民币千元 | D2: 截至2026年6月30日止六个月 | 未经审计 | 币种：人民币 | 报告金额默认单位：人民币千元 | E2: 截至2026年6月30日止六个月 | 未经审计 | 币种：人民币 | 报告金额默认单位：人民币千元 | F2: 截至2026年6月30日止六个月 | 未经审计 | 币种：人民币 | 报告金额默认单位：人民币千元 | G2: 截至2026年6月30日止六个月 | 未经审计 | 币种：人民币 | 报告金额默认单位：人民币千元 | H2: 截至2026年6月30日止六个月 | 未经审计 | 币种：人民币 | 报告金额默认单位：人民币千元
A4: 工作簿状态 | B4: PASS（见 09_校验） | D4: 口径：2026H1对2025H1；资产负债表对2025年末；所有派生指标均为Excel公式。 | E4: 口径：2026H1对2025H1；资产负债表对2025年末；所有派生指标均为Excel公式。 | F4: 口径：2026H1对2025H1；资产负债表对2025年末；所有派生指标均为Excel公式。 | G4: 口径：2026H1对2025H1；资产负债表对2025年末；所有派生指标均为Excel公式。 | H4: 口径：2026H1对2025H1；资产负债表对2025年末；所有派生指标均为Excel公式。
A6: 核心财务指标 | B6: 核心财务指标 | C6: 核心财务指标 | D6: 核心财务指标 | E6: 核心财务指标 | F6: 核心财务指标 | G6: 核心财务指标 | H6: 核心财务指标
A7: 指标 | B7: 2026H1 | C7: 2025H1/期初 | D7: 变动 | E7: 变动率 | F7: 单位 | G7: 来源 | H7: 备注
A8: 营业收入 | B8: ='01_利润表'!B8 -> 19112370 | C8: ='01_利润表'!C8 -> 18137457 | D8: =B8-C8 -> 974913 | E8: =IFERROR(B8/C8-1,0) -> 0.053751361 | F8: 人民币千元 | G8: PDF p3
A9: 毛利 | B9: ='01_利润表'!B11 -> 2419159 | C9: ='01_利润表'!C11 -> 2492873 | D9: =B9-C9 -> -73714 | E9: =IFERROR(B9/C9-1,0) -> -0.029569898 | F9: 人民币千元 | G9: PDF p3
A10: 毛利率 | B10: ='01_利润表'!B11/'01_利润表'!B8 -> 0.12657556 | C10: ='01_利润表'!C11/'01_利润表'!C8 -> 0.13744336 | D10: =B10-C10 -> -0.010867795 | E10: =IFERROR(B10/C10-1,0) -> -0.079071081 | F10: % | G10: 计算 | H10: 毛利/收入
A11: 期内利润 | B11: ='01_利润表'!B24 -> 820008 | C11: ='01_利润表'!C24 -> 837778 | D11: =B11-C11 -> -17770 | E11: =IFERROR(B11/C11-1,0) -> -0.02121087 | F11: 人民币千元 | G11: PDF p3
A12: 归母净利润 | B12: ='01_利润表'!B22 -> 781565 | C12: ='01_利润表'!C22 -> 791992 | D12: =B12-C12 -> -10427 | E12: =IFERROR(B12/C12-1,0) -> -0.013165537 | F12: 人民币千元 | G12: PDF p3
A13: 核心净利润 | B13: 1262600 | C13: 1274900 | D13: =B13-C13 -> -12300 | E13: =IFERROR(B13/C13-1,0) -> -0.0096478155 | F13: 人民币千元 | G13: PDF p1/p36 | H13: 报告摘要的百万元口径换算
A14: 剔除开发商业务后核心净利润 | B14: ='05_核心利润'!B33 -> 1099269 | C14: ='05_核心利润'!C33 -> 1024190 | D14: =B14-C14 -> 75079 | E14: =IFERROR(B14/C14-1,0) -> 0.073305734 | F14: 人民币千元 | G14: PDF p29
A15: 现金及现金等价物 | B15: ='02_资产负债表'!B23 -> 9301898 | C15: ='02_资产负债表'!C23 -> 11084838 | D15: =B15-C15 -> -1782940 | E15: =IFERROR(B15/C15-1,0) -> -0.16084493 | F15: 人民币千元 | G15: PDF p5 | H15: 期末对2025年末
A16: 货币资金 | B16: 10366500 | D16: =B16-C16 -> 10366500 | E16: =IFERROR(B16/C16-1,0) -> 0 | F16: 人民币千元 | G16: PDF p1 | H16: 含受限银行存款及定期存款
A17: 贸易应收款项及应收保证金（净额） | B17: ='07_营运资本'!B12 -> 7002298 | C17: ='07_营运资本'!C12 -> 6004480 | D17: =B17-C17 -> 997818 | E17: =IFERROR(B17/C17-1,0) -> 0.16617892 | F17: 人民币千元 | G17: PDF p14 | H17: 期末对2025年末
A18: 流动比率 | B18: ='02_资产负债表'!B24/'02_资产负债表'!B32 -> 1.0686399 | C18: ='02_资产负债表'!C24/'02_资产负债表'!C32 -> 1.0681477 | D18: =B18-C18 -> 0.00049220839 | E18: =IFERROR(B18/C18-1,0) -> 0.00046080554 | F18: 倍 | G18: 计算 | H18: 流动资产/流动负债
A19: 资产负债率 | B19: =('02_资产负债表'!B32+'02_资产负债表'!B40)/'02_资产负债表'!B25 -> 0.57906617 | C19: =('02_资产负债表'!C32+'02_资产负债表'!C40)/'02_资产负债表'!C25 -> 0.58339365 | D19: =B19-C19 -> -0.0043274758 | E19: =IFERROR(B19/C19-1,0) -> -0.0074177629 | F19: % | G19: 计算 | H19: 负债合计/资产合计
A22: 业务收入与毛利结构 | B22: 业务收入与毛利结构 | C22: 业务收入与毛利结构 | D22: 业务收入与毛利结构 | E22: 业务收入与毛利结构 | F22: 业务收入与毛利结构 | G22: 业务收入与毛利结构 | H22: 业务收入与毛利结构
A23: 业务板块 | B23: 2026H1 | C23: 2025H1
A24: 社区空间居住消费服务 | B24: ='04_收入与毛利'!B8 -> 11951745 | C24: ='04_收入与毛利'!C8 -> 11324996
A25: 商企和城市空间综合服务 | B25: ='04_收入与毛利'!B12 -> 6204698 | C25: ='04_收入与毛利'!C12 -> 5748658
A26: AIoT及BPaaS解决方案服务 | B26: ='04_收入与毛利'!B16 -> 955927 | C26: ='04_收入与毛利'!C16 -> 1063803
A27: 合计 | B27: ='04_收入与毛利'!B19 -> 19112370 | C27: ='04_收入与毛利'!C19 -> 18137457

Sheet 01_利润表
A1: 中期简明合并利润表 | B1: 中期简明合并利润表 | C1: 中期简明合并利润表 | D1: 中期简明合并利润表 | E1: 中期简明合并利润表 | F1: 中期简明合并利润表
A2: 截至2026年6月30日止六个月 | 人民币千元 | B2: 截至2026年6月30日止六个月 | 人民币千元 | C2: 截至2026年6月30日止六个月 | 人民币千元 | D2: 截至2026年6月30日止六个月 | 人民币千元 | E2: 截至2026年6月30日止六个月 | 人民币千元 | F2: 截至2026年6月30日止六个月 | 人民币千元 | G2: 截至2026年6月30日止六个月 | 人民币千元 | H2: 截至2026年6月30日止六个月 | 人民币千元
A5: 项目 | B5: 2026H1 | C5: 2025H1 | D5: 变动额 | E5: 变动率 | F5: 来源
A8: 收入 | B8: 19112370 | C8: 18137457 | D8: =IF(OR(B8="",C8=""),"",B8-C8) -> 974913 | E8: =IFERROR(B8/C8-1,"") -> 0.053751361 | F8: PDF p3
A9: 销售成本 | B9: -16693211 | C9: -15644584 | D9: =IF(OR(B9="",C9=""),"",B9-C9) -> -1048627 | E9: =IFERROR(B9/C9-1,"") -> 0.067028117 | F9: PDF p3
D10: =IF(OR(B10="",C10=""),"",B10-C10) | E10: =IFERROR(B10/C10-1,"")
A11: 毛利 | B11: 2419159 | C11: 2492873 | D11: =IF(OR(B11="",C11=""),"",B11-C11) -> -73714 | E11: =IFERROR(B11/C11-1,"") -> -0.029569898 | F11: PDF p3
A12: 其他收入及收益净额 | B12: 56174 | C12: 63204 | D12: =IF(OR(B12="",C12=""),"",B12-C12) -> -7030 | E12: =IFERROR(B12/C12-1,"") -> -0.11122714 | F12: PDF p3
A13: 销售及分销开支 | B13: -271918 | C13: -298494 | D13: =IF(OR(B13="",C13=""),"",B13-C13) -> 26576 | E13: =IFERROR(B13/C13-1,"") -> -0.089033615 | F13: PDF p3
A14: 行政开支 | B14: -842736 | C14: -885774 | D14: =IF(OR(B14="",C14=""),"",B14-C14) -> 43038 | E14: =IFERROR(B14/C14-1,"") -> -0.048588015 | F14: PDF p3
A15: 金融资产减值亏损净额 | B15: -269942 | C15: -268022 | D15: =IF(OR(B15="",C15=""),"",B15-C15) -> -1920 | E15: =IFERROR(B15/C15-1,"") -> 0.007163591 | F15: PDF p3
A16: 财务成本 | B16: -4014 | C16: -15546 | D16: =IF(OR(B16="",C16=""),"",B16-C16) -> 11532 | E16: =IFERROR(B16/C16-1,"") -> -0.74179853 | F16: PDF p3
A17: 应占合营企业及联营公司利润及亏损 | B17: 3443 | C17: 12367 | D17: =IF(OR(B17="",C17=""),"",B17-C17) -> -8924 | E17: =IFERROR(B17/C17-1,"") -> -0.7215978 | F17: PDF p3
A18: 税前利润 | B18: 1090166 | C18: 1100608 | D18: =IF(OR(B18="",C18=""),"",B18-C18) -> -10442 | E18: =IFERROR(B18/C18-1,"") -> -0.0094874833 | F18: PDF p3
A19: 所得税开支 | B19: -270158 | C19: -262830 | D19: =IF(OR(B19="",C19=""),"",B19-C19) -> -7328 | E19: =IFERROR(B19/C19-1,"") -> 0.02788114 | F19: PDF p3
A20: 期内利润 | B20: 820008 | C20: 837778 | D20: =IF(OR(B20="",C20=""),"",B20-C20) -> -17770 | E20: =IFERROR(B20/C20-1,"") -> -0.02121087 | F20: PDF p3
D21: =IF(OR(B21="",C21=""),"",B21-C21) | E21: =IFERROR(B21/C21-1,"")
A22: 归属于本公司股东 | B22: 781565 | C22: 791992 | D22: =IF(OR(B22="",C22=""),"",B22-C22) -> -10427 | E22: =IFERROR(B22/C22-1,"") -> -0.013165537 | F22: PDF p3
A23: 非控股权益 | B23: 38443 | C23: 45786 | D23: =IF(OR(B23="",C23=""),"",B23-C23) -> -7343 | E23: =IFERROR(B23/C23-1,"") -> -0.16037653 | F23: PDF p3
A24: 归属合计 | B24: 820008 | C24: 837778 | D24: =IF(OR(B24="",C24=""),"",B24-C24) -> -17770 | E24: =IFERROR(B24/C24-1,"") -> -0.02121087 | F24: PDF p3
A25: 每股基本及摊薄盈利（人民币元） | B25: 0.68 | C25: 0.68 | D25: =IF(OR(B25="",C25=""),"",B25-C25) -> 0 | E25: =IFERROR(B25/C25-1,"") -> 0 | F25: PDF p3/p12

Sheet 02_资产负债表
A1: 中期简明合并财务状况表 | B1: 中期简明合并财务状况表 | C1: 中期简明合并财务状况表 | D1: 中期简明合并财务状况表 | E1: 中期简明合并财务状况表 | F1: 中期简明合并财务状况表
A2: 期末：2026年6月30日（未经审计） | 对比：2025年12月31日（经审计） | 人民币千元 | B2: 期末：2026年6月30日（未经审计） | 对比：2025年12月31日（经审计） | 人民币千元 | C2: 期末：2026年6月30日（未经审计） | 对比：2025年12月31日（经审计） | 人民币千元 | D2: 期末：2026年6月30日（未经审计） | 对比：2025年12月31日（经审计） | 人民币千元 | E2: 期末：2026年6月30日（未经审计） | 对比：2025年12月31日（经审计） | 人民币千元 | F2: 期末：2026年6月30日（未经审计） | 对比：2025年12月31日（经审计） | 人民币千元 | G2: 期末：2026年6月30日（未经审计） | 对比：2025年12月31日（经审计） | 人民币千元 | H2: 期末：2026年6月30日（未经审计） | 对比：2025年12月31日（经审计） | 人民币千元
A5: 项目 | B5: 2026-06-30 | C5: 2025-12-31 | D5: 变动额 | E5: 变动率 | F5: 来源
A7: 非流动资产 | D7: =IF(OR(B7="",C7=""),"",B7-C7) | E7: =IFERROR(B7/C7-1,"")
A8: 物业、厂房及设备 | B8: 470811 | C8: 480025 | D8: =IF(OR(B8="",C8=""),"",B8-C8) -> -9214 | E8: =IFERROR(B8/C8-1,"") -> -0.019194834 | F8: PDF p5
A9: 投资性物业 | B9: 2895357 | C9: 2518024 | D9: =IF(OR(B9="",C9=""),"",B9-C9) -> 377333 | E9: =IFERROR(B9/C9-1,"") -> 0.14985282 | F9: PDF p5
A10: 使用权资产 | B10: 219280 | C10: 255735 | D10: =IF(OR(B10="",C10=""),"",B10-C10) -> -36455 | E10: =IFERROR(B10/C10-1,"") -> -0.14254991 | F10: PDF p5
A11: 无形资产 | B11: 7204951 | C11: 7458845 | D11: =IF(OR(B11="",C11=""),"",B11-C11) -> -253894 | E11: =IFERROR(B11/C11-1,"") -> -0.034039318 | F11: PDF p5
A12: 于合营企业及联营公司的投资 | B12: 1236493 | C12: 1244443 | D12: =IF(OR(B12="",C12=""),"",B12-C12) -> -7950 | E12: =IFERROR(B12/C12-1,"") -> -0.0063884003 | F12: PDF p5
A13: FVOCI股权投资 | B13: 961637 | C13: 1192663 | D13: =IF(OR(B13="",C13=""),"",B13-C13) -> -231026 | E13: =IFERROR(B13/C13-1,"") -> -0.19370602 | F13: PDF p5
A14: 递延税项资产 | B14: 604489 | C14: 590545 | D14: =IF(OR(B14="",C14=""),"",B14-C14) -> 13944 | E14: =IFERROR(B14/C14-1,"") -> 0.023612087 | F14: PDF p5
A15: 预付款项、按金及其他应收款项（非流动） | B15: 2617449 | C15: 2609504 | D15: =IF(OR(B15="",C15=""),"",B15-C15) -> 7945 | E15: =IFERROR(B15/C15-1,"") -> 0.0030446399 | F15: PDF p5
A16: 非流动资产总额 | B16: 16210467 | C16: 16349784 | D16: =IF(OR(B16="",C16=""),"",B16-C16) -> -139317 | E16: =IFERROR(B16/C16-1,"") -> -0.00852103 | F16: PDF p5
A17: 流动资产 | D17: =IF(OR(B17="",C17=""),"",B17-C17) | E17: =IFERROR(B17/C17-1,"")
A18: 存货 | B18: 372569 | C18: 207768 | D18: =IF(OR(B18="",C18=""),"",B18-C18) -> 164801 | E18: =IFERROR(B18/C18-1,"") -> 0.79319722 | F18: PDF p5
A19: 贸易应收款项及应收保证金 | B19: 7002298 | C19: 6004480 | D19: =IF(OR(B19="",C19=""),"",B19-C19) -> 997818 | E19: =IFERROR(B19/C19-1,"") -> 0.16617892 | F19: PDF p5
A20: 预付款项、按金及其他应收款项（流动） | B20: 2515993 | C20: 2388548 | D20: =IF(OR(B20="",C20=""),"",B20-C20) -> 127445 | E20: =IFERROR(B20/C20-1,"") -> 0.053356684 | F20: PDF p5
A21: 受限制银行存款 | B21: 997667 | C21: 931940 | D21: =IF(OR(B21="",C21=""),"",B21-C21) -> 65727 | E21: =IFERROR(B21/C21-1,"") -> 0.070527073 | F21: PDF p5
A22: 原到期日超过三个月的定期存款 | B22: 66935 | C22: 72939 | D22: =IF(OR(B22="",C22=""),"",B22-C22) -> -6004 | E22: =IFERROR(B22/C22-1,"") -> -0.082315359 | F22: PDF p5
A23: 现金及现金等价物 | B23: 9301898 | C23: 11084838 | D23: =IF(OR(B23="",C23=""),"",B23-C23) -> -1782940 | E23: =IFERROR(B23/C23-1,"") -> -0.16084493 | F23: PDF p5
A24: 流动资产总额 | B24: 20257360 | C24: 20690513 | D24: =IF(OR(B24="",C24=""),"",B24-C24) -> -433153 | E24: =IFERROR(B24/C24-1,"") -> -0.02093486 | F24: PDF p5
A25: 资产总额（计算） | B25: =B16+B24 -> 36467827 | C25: =C16+C24 -> 37040297 | D25: =IF(OR(B25="",C25=""),"",B25-C25) -> -572470 | E25: =IFERROR(B25/C25-1,"") -> -0.01545533 | F25: 计算
A26: 流动负债 | D26: =IF(OR(B26="",C26=""),"",B26-C26) | E26: =IFERROR(B26/C26-1,"")
A27: 贸易应付款项及应付票据 | B27: 6922203 | C27: 6805435 | D27: =IF(OR(B27="",C27=""),"",B27-C27) -> 116768 | E27: =IFERROR(B27/C27-1,"") -> 0.017158051 | F27: PDF p5
A28: 合同负债 | B28: 4986860 | C28: 4904389 | D28: =IF(OR(B28="",C28=""),"",B28-C28) -> 82471 | E28: =IFERROR(B28/C28-1,"") -> 0.016815754 | F28: PDF p5
A29: 其他应付款项及应计项目（流动） | B29: 6020327 | C29: 6502131 | D29: =IF(OR(B29="",C29=""),"",B29-C29) -> -481804 | E29: =IFERROR(B29/C29-1,"") -> -0.074099399 | F29: PDF p5
A30: 租赁负债（流动） | B30: 84880 | C30: 91735 | D30: =IF(OR(B30="",C30=""),"",B30-C30) -> -6855 | E30: =IFERROR(B30/C30-1,"") -> -0.074726113 | F30: PDF p5
A31: 应纳税项 | B31: 941937 | C31: 1066770 | D31: =IF(OR(B31="",C31=""),"",B31-C31) -> -124833 | E31: =IFERROR(B31/C31-1,"") -> -0.1170196 | F31: PDF p5
A32: 流动负债总额 | B32: 18956207 | C32: 19370460 | D32: =IF(OR(B32="",C32=""),"",B32-C32) -> -414253 | E32: =IFERROR(B32/C32-1,"") -> -0.021385811 | F32: PDF p5
A33: 流动资产净额 | B33: 1301153 | C33: 1320053 | D33: =IF(OR(B33="",C33=""),"",B33-C33) -> -18900 | E33: =IFERROR(B33/C33-1,"") -> -0.014317607 | F33: PDF p5
A34: 资产总额减流动负债 | B34: 17511620 | C34: 17669837 | D34: =IF(OR(B34="",C34=""),"",B34-C34) -> -158217 | E34: =IFERROR(B34/C34-1,"") -> -0.0089540724 | F34: PDF p5
A35: 非流动负债 | D35: =IF(OR(B35="",C35=""),"",B35-C35) | E35: =IFERROR(B35/C35-1,"")
A36: 其他应付款项及应计项目（非流动） | B36: 1219938 | C36: 1203173 | D36: =IF(OR(B36="",C36=""),"",B36-C36) -> 16765 | E36: =IFERROR(B36/C36-1,"") -> 0.01393399 | F36: PDF p6
A37: 拨备 | B37: 105229 | C37: 106943 | D37: =IF(OR(B37="",C37=""),"",B37-C37) -> -1714 | E37: =IFERROR(B37/C37-1,"") -> -0.016027229 | F37: PDF p6
A38: 租赁负债（非流动） | B38: 148566 | C38: 181794 | D38: =IF(OR(B38="",C38=""),"",B38-C38) -> -33228 | E38: =IFERROR(B38/C38-1,"") -> -0.18277831 | F38: PDF p6
A39: 递延税项负债 | B39: 687345 | C39: 746704 | D39: =IF(OR(B39="",C39=""),"",B39-C39) -> -59359 | E39: =IFERROR(B39/C39-1,"") -> -0.079494686 | F39: PDF p6
A40: 非流动负债总额 | B40: 2161078 | C40: 2238614 | D40: =IF(OR(B40="",C40=""),"",B40-C40) -> -77536 | E40: =IFERROR(B40/C40-1,"") -> -0.034635717 | F40: PDF p6
A41: 资产净额 | B41: 15350542 | C41: 15431223 | D41: =IF(OR(B41="",C41=""),"",B41-C41) -> -80681 | E41: =IFERROR(B41/C41-1,"") -> -0.0052284255 | F41: PDF p6
A42: 权益 | D42: =IF(OR(B42="",C42=""),"",B42-C42) | E42: =IFERROR(B42/C42-1,"")
A43: 股本 | B43: 1168053 | C43: 1168053 | D43: =IF(OR(B43="",C43=""),"",B43-C43) -> 0 | E43: =IFERROR(B43/C43-1,"") -> 0 | F43: PDF p6
...

Sheet 03_全面收益
A1: 中期简明合并全面收益表 | B1: 中期简明合并全面收益表 | C1: 中期简明合并全面收益表 | D1: 中期简明合并全面收益表 | E1: 中期简明合并全面收益表 | F1: 中期简明合并全面收益表
A2: 截至2026年6月30日止六个月 | 人民币千元 | B2: 截至2026年6月30日止六个月 | 人民币千元 | C2: 截至2026年6月30日止六个月 | 人民币千元 | D2: 截至2026年6月30日止六个月 | 人民币千元 | E2: 截至2026年6月30日止六个月 | 人民币千元 | F2: 截至2026年6月30日止六个月 | 人民币千元 | G2: 截至2026年6月30日止六个月 | 人民币千元 | H2: 截至2026年6月30日止六个月 | 人民币千元
A5: 项目 | B5: 2026H1 | C5: 2025H1 | D5: 变动额 | E5: 变动率 | F5: 来源
A7: 期内利润 | B7: 820008 | C7: 837778 | D7: =B7-C7 -> -17770 | E7: =IFERROR(B7/C7-1,"") -> -0.02121087 | F7: PDF p4
A8: 换算海外业务的汇兑差额 | B8: -2449 | C8: -5033 | D8: =B8-C8 -> 2584 | E8: =IFERROR(B8/C8-1,"") -> -0.51341148 | F8: PDF p4
A9: FVOCI股权投资公允价值变动 | B9: -231026 | C9: -175083 | D9: =B9-C9 -> -55943 | E9: =IFERROR(B9/C9-1,"") -> 0.31952274 | F9: PDF p4
A10: 期内其他全面亏损，扣除税项 | B10: -233475 | C10: -180116 | D10: =B10-C10 -> -53359 | E10: =IFERROR(B10/C10-1,"") -> 0.29624797 | F10: PDF p4
A11: 期内全面收益总额 | B11: 586533 | C11: 657662 | D11: =B11-C11 -> -71129 | E11: =IFERROR(B11/C11-1,"") -> -0.10815434 | F11: PDF p4
A12: 归属于本公司股东 | B12: 548090 | C12: 611876 | D12: =B12-C12 -> -63786 | E12: =IFERROR(B12/C12-1,"") -> -0.10424661 | F12: PDF p4
A13: 归属于非控股权益 | B13: 38443 | C13: 45786 | D13: =B13-C13 -> -7343 | E13: =IFERROR(B13/C13-1,"") -> -0.16037653 | F13: PDF p4
A14: 归属合计 | B14: 586533 | C14: 657662 | D14: =B14-C14 -> -71129 | E14: =IFERROR(B14/C14-1,"") -> -0.10815434 | F14: PDF p4

Sheet 04_收入与毛利
A1: 分业务收入与毛利 | B1: 分业务收入与毛利 | C1: 分业务收入与毛利 | D1: 分业务收入与毛利 | E1: 分业务收入与毛利 | F1: 分业务收入与毛利 | G1: 分业务收入与毛利 | H1: 分业务收入与毛利 | I1: 分业务收入与毛利 | J1: 分业务收入与毛利
A2: 截至2026年6月30日止六个月 | 人民币千元 | 收入占比、毛利率和增长率均为公式 | B2: 截至2026年6月30日止六个月 | 人民币千元 | 收入占比、毛利率和增长率均为公式 | C2: 截至2026年6月30日止六个月 | 人民币千元 | 收入占比、毛利率和增长率均为公式 | D2: 截至2026年6月30日止六个月 | 人民币千元 | 收入占比、毛利率和增长率均为公式 | E2: 截至2026年6月30日止六个月 | 人民币千元 | 收入占比、毛利率和增长率均为公式 | F2: 截至2026年6月30日止六个月 | 人民币千元 | 收入占比、毛利率和增长率均为公式 | G2: 截至2026年6月30日止六个月 | 人民币千元 | 收入占比、毛利率和增长率均为公式 | H2: 截至2026年6月30日止六个月 | 人民币千元 | 收入占比、毛利率和增长率均为公式
A5: 业务板块/服务 | B5: 2026收入 | C5: 2025收入 | D5: 2026占比 | E5: 2025占比 | F5: 收入增长 | G5: 2026毛利 | H5: 2025毛利 | I5: 2026毛利率 | J5: 2025毛利率
A8: 社区空间居住消费服务 | B8: 11951745 | C8: 11324996 | D8: =B8/$B$19 -> 0.62534081 | E8: =C8/$C$19 -> 0.62439823 | F8: =B8/C8-1 -> 0.055342095 | G8: 1684792 | H8: 1634641 | I8: =G8/B8 -> 0.14096619 | J8: =H8/C8 -> 0.14433921
A9: 住宅物业服务 | B9: 10943537 | C9: 10279326 | D9: =B9/$B$19 -> 0.57258922 | E9: =C9/$C$19 -> 0.56674571 | F9: =B9/C9-1 -> 0.064616201 | G9: 1416503 | H9: 1330417 | I9: =G9/B9 -> 0.1294374 | J9: =H9/C9 -> 0.12942648
A10: 居住相关资产服务 | B10: 903092 | C10: 858423 | D10: =B10/$B$19 -> 0.047251701 | E10: =C10/$C$19 -> 0.047328741 | F10: =B10/C10-1 -> 0.052036117 | G10: 209838 | H10: 191554 | I10: =G10/B10 -> 0.23235506 | J10: =H10/C10 -> 0.2231464
A11: 其他社区增值服务 | B11: 105116 | C11: 187247 | D11: =B11/$B$19 -> 0.0054998935 | E11: =C11/$C$19 -> 0.010323774 | F11: =B11/C11-1 -> -0.43862385 | G11: 58451 | H11: 112670 | I11: =G11/B11 -> 0.55606187 | J11: =H11/C11 -> 0.60171859
A12: 商企和城市空间综合服务 | B12: 6204698 | C12: 5748658 | D12: =B12/$B$19 -> 0.32464305 | E12: =C12/$C$19 -> 0.3169495 | F12: =B12/C12-1 -> 0.079329819 | G12: 440536 | H12: 506908 | I12: =G12/B12 -> 0.071000394 | J12: =H12/C12 -> 0.088178493
A13: 物业及设施管理服务 | B13: 5627822 | C13: 5169132 | D13: =B13/$B$19 -> 0.29445966 | E13: =C13/$C$19 -> 0.28499762 | F13: =B13/C13-1 -> 0.088736368 | G13: 412207 | H13: 452812 | I13: =G13/B13 -> 0.073244498 | J13: =H13/C13 -> 0.087599233
A14: 开发商增值服务 | B14: 176985 | C14: 219285 | D14: =B14/$B$19 -> 0.009260233 | E14: =C14/$C$19 -> 0.012090173 | F14: =B14/C14-1 -> -0.19289965 | G14: 6321 | H14: 21333 | I14: =G14/B14 -> 0.035714891 | J14: =H14/C14 -> 0.097284356
A15: 城市空间整合服务 | B15: 399891 | C15: 360241 | D15: =B15/$B$19 -> 0.020923151 | E15: =C15/$C$19 -> 0.019861715 | F15: =B15/C15-1 -> 0.11006521 | G15: 22008 | H15: 32763 | I15: =G15/B15 -> 0.055034997 | J15: =H15/C15 -> 0.090947449
A16: AIoT及BPaaS解决方案服务 | B16: 955927 | C16: 1063803 | D16: =B16/$B$19 -> 0.050016141 | E16: =C16/$C$19 -> 0.058652269 | F16: =B16/C16-1 -> -0.10140599 | G16: 293831 | H16: 351324 | I16: =G16/B16 -> 0.30737807 | J16: =H16/C16 -> 0.33025288
A17: AIoT解决方案 | B17: 174522 | C17: 203719 | D17: =B17/$B$19 -> 0.0091313636 | E17: =C17/$C$19 -> 0.011231949 | F17: =B17/C17-1 -> -0.14331997 | G17: 22683 | H17: 26687 | I17: =G17/B17 -> 0.12997215 | J17: =H17/C17 -> 0.13099907
A18: BPaaS解决方案 | B18: 781405 | C18: 860084 | D18: =B18/$B$19 -> 0.040884778 | E18: =C18/$C$19 -> 0.047420319 | F18: =B18/C18-1 -> -0.091478274 | G18: 271148 | H18: 324637 | I18: =G18/B18 -> 0.3470006 | J18: =H18/C18 -> 0.37744802
A19: 合计 | B19: 19112370 | C19: 18137457 | D19: =B19/$B$19 -> 1 | E19: =C19/$C$19 -> 1 | F19: =B19/C19-1 -> 0.053751361 | G19: 2419159 | H19: 2492873 | I19: =G19/B19 -> 0.12657556 | J19: =H19/C19 -> 0.13744336
A21: 物管 | B21: =B9+B13+B15 -> 16971250 | C21: =C9+C13+C15 -> 15808699 | D21: =D9+D13+D15 -> 0.88797203 | E21: =E9+E13+E15 -> 0.87160504 | F21: =F9+F13+F15 -> 0.26341778 | G21: =G9+G13+G15 -> 1850718 | H21: =H9+H13+H15 -> 1815992 | I21: =I9+I13+I15 -> 0.2577169 | J21: =J9+J13+J15 -> 0.30797316
A22: 社区增值 | B22: =B10+B11 -> 1008208 | C22: =C10+C11 -> 1045670 | D22: =D10+D11 -> 0.052751595 | E22: =E10+E11 -> 0.057652514 | F22: =F10+F11 -> -0.38658773 | G22: =G10+G11 -> 268289 | H22: =H10+H11 -> 304224 | I22: =I10+I11 -> 0.78841694 | J22: =J10+J11 -> 0.82486498
A23: 非业主增值 | B23: =B14 -> 176985 | C23: =C14 -> 219285 | D23: =D14 -> 0.009260233 | E23: =E14 -> 0.012090173 | F23: =F14 -> -0.19289965 | G23: =G14 -> 6321 | H23: =H14 -> 21333 | I23: =I14 -> 0.035714891 | J23: =J14 -> 0.097284356
A24: AIoT及BPaaS | B24: =B16 -> 955927 | C24: =C16 -> 1063803 | D24: =D16 -> 0.050016141 | E24: =E16 -> 0.058652269 | F24: =F16 -> -0.10140599 | G24: =G16 -> 293831 | H24: =H16 -> 351324 | I24: =I16 -> 0.30737807 | J24: =J16 -> 0.33025288
A26: 收入确认时间 | B26: 收入确认时间 | C26: 收入确认时间 | D26: 收入确认时间 | E26: 收入确认时间 | F26: 收入确认时间 | G26: 收入确认时间 | H26: 收入确认时间 | I26: 收入确认时间 | J26: 收入确认时间
A27: 类别 | B27: 2026H1 | C27: 2025H1 | D27: 变动额 | E27: 变动率 | F27: 来源
A28: 于某一时间点转移的商品或服务 | B28: 551709 | C28: 597029 | D28: =B28-C28 -> -45320 | E28: =B28/C28-1 -> -0.07590921 | F28: PDF p9
A29: 随时间转移的服务 | B29: 18560661 | C29: 17540428 | D29: =B29-C29 -> 1020233 | E29: =B29/C29-1 -> 0.058164658 | F29: PDF p9
A30: 客户合约收入总额 | B30: 19112370 | C30: 18137457 | D30: =B30-C30 -> 974913 | E30: =B30/C30-1 -> 0.053751361 | F30: PDF p9

Sheet 05_核心利润
A1: 剔除开发商业务后的经营桥接 | B1: 剔除开发商业务后的经营桥接 | C1: 剔除开发商业务后的经营桥接 | D1: 剔除开发商业务后的经营桥接 | E1: 剔除开发商业务后的经营桥接 | F1: 剔除开发商业务后的经营桥接
A2: 截至2026年6月30日止六个月 | 人民币千元 | B2: 截至2026年6月30日止六个月 | 人民币千元 | C2: 截至2026年6月30日止六个月 | 人民币千元 | D2: 截至2026年6月30日止六个月 | 人民币千元 | E2: 截至2026年6月30日止六个月 | 人民币千元 | F2: 截至2026年6月30日止六个月 | 人民币千元 | G2: 截至2026年6月30日止六个月 | 人民币千元 | H2: 截至2026年6月30日止六个月 | 人民币千元
A5: 分类/项目 | B5: 2026H1 | C5: 2025H1 | D5: 变动额 | E5: 变动率 | F5: 来源
A7: 收入 - 循环型业务 | D7: =IF(OR(B7="",C7=""),"",B7-C7) | E7: =IFERROR(B7/C7-1,"")
A8: 住宅物业服务 | B8: 10797984 | C8: 10079737 | D8: =IF(OR(B8="",C8=""),"",B8-C8) -> 718247 | E8: =IFERROR(B8/C8-1,"") -> 0.071256522 | F8: PDF p28
A9: 物业及设施管理服务 | B9: 5238913 | C9: 4724735 | D9: =IF(OR(B9="",C9=""),"",B9-C9) -> 514178 | E9: =IFERROR(B9/C9-1,"") -> 0.10882684 | F9: PDF p28
A10: BPaaS解决方案 | B10: 643345 | C10: 617644 | D10: =IF(OR(B10="",C10=""),"",B10-C10) -> 25701 | E10: =IFERROR(B10/C10-1,"") -> 0.041611349 | F10: PDF p28
A11: 收入 - 循环型业务小计 | B11: 16680242 | C11: 15422116 | D11: =IF(OR(B11="",C11=""),"",B11-C11) -> 1258126 | E11: =IFERROR(B11/C11-1,"") -> 0.081579337 | F11: PDF p28
A12: 收入 - 其他核心业务 | D12: =IF(OR(B12="",C12=""),"",B12-C12) | E12: =IFERROR(B12/C12-1,"")
A13: 居住相关资产服务 | B13: 871866 | C13: 763107 | D13: =IF(OR(B13="",C13=""),"",B13-C13) -> 108759 | E13: =IFERROR(B13/C13-1,"") -> 0.1425213 | F13: PDF p28
A14: AIoT解决方案 | B14: 124479 | C14: 89562 | D14: =IF(OR(B14="",C14=""),"",B14-C14) -> 34917 | E14: =IFERROR(B14/C14-1,"") -> 0.389864 | F14: PDF p28
A15: 收入 - 核心业务小计 | B15: 17676587 | C15: 16274785 | D15: =IF(OR(B15="",C15=""),"",B15-C15) -> 1401802 | E15: =IFERROR(B15/C15-1,"") -> 0.086133365 | F15: PDF p28
A16: 收入 - 其他业务 | D16: =IF(OR(B16="",C16=""),"",B16-C16) | E16: =IFERROR(B16/C16-1,"")
A17: 其他社区增值服务 | B17: 74833 | C17: 182187 | D17: =IF(OR(B17="",C17=""),"",B17-C17) -> -107354 | E17: =IFERROR(B17/C17-1,"") -> -0.5892517 | F17: PDF p28
A18: 城市空间整合服务 | B18: 382736 | C18: 339555 | D18: =IF(OR(B18="",C18=""),"",B18-C18) -> 43181 | E18: =IFERROR(B18/C18-1,"") -> 0.12716938 | F18: PDF p28
A19: 收入 - 其他业务小计 | B19: 457569 | C19: 521742 | D19: =IF(OR(B19="",C19=""),"",B19-C19) -> -64173 | E19: =IFERROR(B19/C19-1,"") -> -0.12299757 | F19: PDF p28
A20: 剔除所有开发商业务后收入 | B20: 18134156 | C20: 16796527 | D20: =IF(OR(B20="",C20=""),"",B20-C20) -> 1337629 | E20: =IFERROR(B20/C20-1,"") -> 0.079637237 | F20: PDF p28
A21: 毛利 - 循环型业务 | B21: 1883920 | C21: 1797027 | D21: =IF(OR(B21="",C21=""),"",B21-C21) -> 86893 | E21: =IFERROR(B21/C21-1,"") -> 0.048353753 | F21: PDF p29
A22: 毛利 - 核心业务 | B22: 2104051 | C22: 1961440 | D22: =IF(OR(B22="",C22=""),"",B22-C22) -> 142611 | E22: =IFERROR(B22/C22-1,"") -> 0.072707297 | F22: PDF p29
A23: 毛利 - 其他业务 | B23: 62548 | C23: 143210 | D23: =IF(OR(B23="",C23=""),"",B23-C23) -> -80662 | E23: =IFERROR(B23/C23-1,"") -> -0.56324279 | F23: PDF p29
A24: 剔除所有开发商业务后毛利 | B24: 2166599 | C24: 2104650 | D24: =IF(OR(B24="",C24=""),"",B24-C24) -> 61949 | E24: =IFERROR(B24/C24-1,"") -> 0.029434348 | F24: PDF p29
A25: 销售及分销开支 | B25: -271918 | C25: -298494 | D25: =IF(OR(B25="",C25=""),"",B25-C25) -> 26576 | E25: =IFERROR(B25/C25-1,"") -> -0.089033615 | F25: PDF p29
A26: 行政开支 | B26: -807901 | C26: -831889 | D26: =IF(OR(B26="",C26=""),"",B26-C26) -> 23988 | E26: =IFERROR(B26/C26-1,"") -> -0.028835578 | F26: PDF p29
A27: 其他支出 | B27: -144985 | C27: -110550 | D27: =IF(OR(B27="",C27=""),"",B27-C27) -> -34435 | E27: =IFERROR(B27/C27-1,"") -> 0.31148801 | F27: PDF p29
A28: 所得税开支 | B28: -229276 | C28: -187070 | D28: =IF(OR(B28="",C28=""),"",B28-C28) -> -42206 | E28: =IFERROR(B28/C28-1,"") -> 0.22561608 | F28: PDF p29
... A33: 剔除所有开发商业务后的核心净利润 | B33: 1099269 | C33: 1024190 | D33: =IF(OR(B33="",C33=""),"",B33-C33) -> 75079 | E33: =IFERROR(B33/C33-1,"") -> 0.073305734 | F33: PDF p29

Sheet 06_经营指标
A1: 经营与业务规模指标 | B1: 经营与业务规模指标 | C1: 经营与业务规模指标 | D1: 经营与业务规模指标 | E1: 经营与业务规模指标 | F1: 经营与业务规模指标 | G1: 经营与业务规模指标
A2: 报告披露的经营数据；不同单位不混合求和 | B2: 报告披露的经营数据；不同单位不混合求和 | C2: 报告披露的经营数据；不同单位不混合求和 | D2: 报告披露的经营数据；不同单位不混合求和 | E2: 报告披露的经营数据；不同单位不混合求和 | F2: 报告披露的经营数据；不同单位不混合求和 | G2: 报告披露的经营数据；不同单位不混合求和 | H2: 报告披露的经营数据；不同单位不混合求和
A5: 主题 | B5: 指标 | C5: 2026H1/期末 | D5: 2025H1/期初 | E5: 变动率/差值 | F5: 单位 | G5: 来源
A7: 住宅物业 | B7: 合约饱和收入 | C7: 34891.8 | D7: 33791.1 | E7: =IF(D7="","",IF(F7="%",C7-D7,C7/D7-1)) -> 0.032573666 | F7: 人民币百万元 | G7: PDF p30
A8: 住宅物业 | B8: 合约项目数 | C8: 5445 | D8: 5178 | E8: =IF(D8="","",IF(F8="%",C8-D8,C8/D8-1)) -> 0.051564311 | F8: 个 | G8: PDF p30
A9: 住宅物业 | B9: 在管饱和收入 | C9: 29556.6 | D9: 28133.5 | E9: =IF(D9="","",IF(F9="%",C9-D9,C9/D9-1)) -> 0.050583824 | F9: 人民币百万元 | G9: PDF p30
A10: 住宅物业 | B10: 在管项目数 | C10: 4680 | D10: 4408 | E10: =IF(D10="","",IF(F10="%",C10-D10,C10/D10-1)) -> 0.061705989 | F10: 个 | G10: PDF p30
A11: 物业及设施管理 | B11: 合约饱和收入 | C11: 22303.2 | D11: 19837.9 | E11: =IF(D11="","",IF(F11="%",C11-D11,C11/D11-1)) -> 0.12427223 | F11: 人民币百万元 | G11: PDF p31
A12: 物业及设施管理 | B12: 合约项目数 | C12: 3543 | D12: 3284 | E12: =IF(D12="","",IF(F12="%",C12-D12,C12/D12-1)) -> 0.078867235 | F12: 个 | G12: PDF p31
A13: 物业及设施管理 | B13: 在管饱和收入 | C13: 17285.3 | D13: 15700 | E13: =IF(D13="","",IF(F13="%",C13-D13,C13/D13-1)) -> 0.10097452 | F13: 人民币百万元 | G13: PDF p31
A14: 物业及设施管理 | B14: 在管项目数 | C14: 2610 | D14: 2585 | E14: =IF(D14="","",IF(F14="%",C14-D14,C14/D14-1)) -> 0.0096711799 | F14: 个 | G14: PDF p31
A15: 项目组合 | B15: 新签约住宅项目 | C15: 207 | E15: =IF(D15="","",IF(F15="%",C15-D15,C15/D15-1)) | F15: 个 | G15: PDF p22
A16: 项目组合 | B16: 新签约住宅年化饱和收入 | C16: 835 | E16: =IF(D16="","",IF(F16="%",C16-D16,C16/D16-1)) | F16: 人民币百万元 | G16: PDF p22
A17: 项目组合 | B17: 主动退出住宅项目 | C17: 139 | E17: =IF(D17="","",IF(F17="%",C17-D17,C17/D17-1)) | F17: 个 | G17: PDF p22
A18: 项目组合 | B18: 退出住宅项目年化饱和收入 | C18: 742.7 | E18: =IF(D18="","",IF(F18="%",C18-D18,C18/D18-1)) | F18: 人民币百万元 | G18: PDF p22
A19: 项目组合 | B19: 蝶城数量 | C19: 708 | E19: =IF(D19="","",IF(F19="%",C19-D19,C19/D19-1)) | F19: 个 | G19: PDF p22
A20: 居住服务 | B20: 二手买卖新增签约业绩 | C20: 189 | E20: =IF(D20="","",IF(F20="%",C20-D20,C20/D20-1)) | F20: 人民币百万元 | G20: PDF p23
A21: 居住服务 | B21: 二手买卖成交单数 | C21: 6429 | E21: =IF(D21="","",IF(F21="%",C21-D21,C21/D21-1)) | F21: 单 | G21: PDF p23
A22: 居住服务 | B22: 房屋修缮业务收入 | C22: 313 | E22: =IF(D22="","",IF(F22="%",C22-D22,C22/D22-1)) | F22: 人民币百万元 | G22: PDF p23
A23: 人力 | B23: 员工人数 | C23: 103982 | D23: 108745 | E23: =IF(D23="","",IF(F23="%",C23-D23,C23/D23-1)) -> -0.043799715 | F23: 人 | G23: PDF p38
A24: 人力 | B24: 员工成本 | C24: 6238.1 | E24: =IF(D24="","",IF(F24="%",C24-D24,C24/D24-1)) | F24: 人民币百万元 | G24: PDF p38
A25: 科技 | B25: 财翠翠AI审批量 | C25: 829231 | E25: =IF(D25="","",IF(F25="%",C25-D25,C25/D25-1)) | F25: 单 | G25: PDF p25
A26: 科技 | B26: 可可上线项目 | C26: 4140 | E26: =IF(D26="","",IF(F26="%",C26-D26,C26/D26-1)) | F26: 个 | G26: PDF p25
A27: 科技 | B27: 灵石产品签约租赁 | C27: 1339 | E27: =IF(D27="","",IF(F27="%",C27-D27,C27/D27-1)) | F27: 台 | G27: PDF p25
A28: 科技 | B28: 灵石已交付 | C28: 472 | E28: =IF(D28="","",IF(F28="%",C28-D28,C28/D28-1)) | F28: 台 | G28: PDF p25
A29: 能源 | B29: 存量能耗项目 | C29: 172 | E29: =IF(D29="","",IF(F29="%",C29-D29,C29/D29-1)) | F29: 个 | G29: PDF p24
A30: 能源 | B30: 节能率 | C30: 0.096 | E30: =IF(D30="","",IF(F30="%",C30-D30,C30/D30-1)) | F30: % | G30: PDF p24

Sheet 07_营运资本
A1: 营运资本与信用风险 | B1: 营运资本与信用风险 | C1: 营运资本与信用风险 | D1: 营运资本与信用风险 | E1: 营运资本与信用风险 | F1: 营运资本与信用风险
A2: 期末：2026年6月30日 | 对比：2025年12月31日 | 人民币千元 | B2: 期末：2026年6月30日 | 对比：2025年12月31日 | 人民币千元 | C2: 期末：2026年6月30日 | 对比：2025年12月31日 | 人民币千元 | D2: 期末：2026年6月30日 | 对比：2025年12月31日 | 人民币千元 | E2: 期末：2026年6月30日 | 对比：2025年12月31日 | 人民币千元 | F2: 期末：2026年6月30日 | 对比：2025年12月31日 | 人民币千元 | G2: 期末：2026年6月30日 | 对比：2025年12月31日 | 人民币千元 | H2: 期末：2026年6月30日 | 对比：2025年12月31日 | 人民币千元
A4: 贸易应收款项及应收保证金 | B4: 贸易应收款项及应收保证金 | C4: 贸易应收款项及应收保证金 | D4: 贸易应收款项及应收保证金 | E4: 贸易应收款项及应收保证金 | F4: 贸易应收款项及应收保证金
A5: 项目 | B5: 2026-06-30 | C5: 2025-12-31 | D5: 变动额 | E5: 变动率 | F5: 来源
A7: 关联方贸易应收款项及应收票据 | B7: 1774106 | C7: 2064317 | D7: =B7-C7 -> -290211 | E7: =IFERROR(B7/C7-1,"") -> -0.14058451 | F7: PDF p14
A8: 第三方贸易应收款项及应收票据 | B8: 7071917 | C8: 5615849 | D8: =B8-C8 -> 1456068 | E8: =IFERROR(B8/C8-1,"") -> 0.25927834 | F8: PDF p14
A9: 应收保证金 | B9: 8409 | C9: 15322 | D9: =B9-C9 -> -6913 | E9: =IFERROR(B9/C9-1,"") -> -0.45118131 | F9: PDF p14
A10: 总账面值 | B10: 8854432 | C10: 7695488 | D10: =B10-C10 -> 1158944 | E10: =IFERROR(B10/C10-1,"") -> 0.15060046 | F10: PDF p14
A11: 减：减值拨备 | B11: -1852134 | C11: -1691008 | D11: =B11-C11 -> -161126 | E11: =IFERROR(B11/C11-1,"") -> 0.095283996 | F11: PDF p14
A12: 账面净值 | B12: 7002298 | C12: 6004480 | D12: =B12-C12 -> 997818 | E12: =IFERROR(B12/C12-1,"") -> 0.16617892 | F12: PDF p14
A15: 贸易应收账龄（扣除亏损拨备） | B15: 贸易应收账龄（扣除亏损拨备） | C15: 贸易应收账龄（扣除亏损拨备） | D15: 贸易应收账龄（扣除亏损拨备） | E15: 贸易应收账龄（扣除亏损拨备） | F15: 贸易应收账龄（扣除亏损拨备）
A16: 账龄 | B16: 2026-06-30 | C16: 2025-12-31 | D16: 变动额 | E16: 变动率 | F16: 来源
A18: 1年内 | B18: 6422516 | C18: 5189232 | D18: =B18-C18 -> 1233284 | E18: =IFERROR(B18/C18-1,"") -> 0.23766214 | F18: PDF p15
A19: 1至2年 | B19: 272012 | C19: 459262 | D19: =B19-C19 -> -187250 | E19: =IFERROR(B19/C19-1,"") -> -0.40771934 | F19: PDF p15
A20: 2至3年 | B20: 161655 | C20: 247708 | D20: =B20-C20 -> -86053 | E20: =IFERROR(B20/C20-1,"") -> -0.34739694 | F20: PDF p15
A21: 3年以上 | B21: 146115 | C21: 108278 | D21: =B21-C21 -> 37837 | E21: =IFERROR(B21/C21-1,"") -> 0.3494431 | F21: PDF p15
A22: 合计 | B22: 7002298 | C22: 6004480 | D22: =B22-C22 -> 997818 | E22: =IFERROR(B22/C22-1,"") -> 0.16617892 | F22: PDF p15
A25: 预期信用亏损暴露 | B25: 预期信用亏损暴露 | C25: 预期信用亏损暴露 | D25: 预期信用亏损暴露 | E25: 预期信用亏损暴露 | F25: 预期信用亏损暴露
A26: 类别 | B26: 2026总账面值 | C26: 2026 ECL | D26: 2026 ECL率 | E26: 2025 ECL率 | F26: 来源
A28: 第三方-少于1年 | B28: 5745469 | C28: 147409 | D28: 0.0257 | E28: 0.028 | F28: PDF p15
A29: 第三方-1至3年 | B29: 529893 | C29: 208920 | D29: 0.3943 | E29: 0.3632 | F29: PDF p15
A30: 第三方-3年以上 | B30: 804964 | C30: 664036 | D30: 0.8249 | E30: 0.807 | F30: PDF p15
A31: 关联方 | B31: 1774106 | C31: 831769 | D31: 0.4688 | E31: 0.3868 | F31: PDF p15
A32: 合计 | B32: 8854432 | C32: 1852134 | F32: PDF p15
A35: 贸易应付款项及应付票据 | B35: 贸易应付款项及应付票据 | C35: 贸易应付款项及应付票据 | D35: 贸易应付款项及应付票据 | E35: 贸易应付款项及应付票据 | F35: 贸易应付款项及应付票据
A36: 项目 | B36: 2026-06-30 | C36: 2025-12-31 | D36: 变动额 | E36: 变动率 | F36: 来源
A38: 关联方 | B38: 455124 | C38: 346640 | D38: =B38-C38 -> 108484 | E38: =IFERROR(B38/C38-1,"") -> 0.31295869 | F38: PDF p17
A39: 第三方 | B39: 6467079 | C39: 6458795 | D39: =B39-C39 -> 8284 | E39: =IFERROR(B39/C39-1,"") -> 0.0012825922 | F39: PDF p17
A40: 合计 | B40: 6922203 | C40: 6805435 | D40: =B40-C40 -> 116768 | E40: =IFERROR(B40/C40-1,"") -> 0.017158051 | F40: PDF p17
A41: 1年内 | B41: 6222676 | C41: 6343118 | D41: =B41-C41 -> -120442 | E41: =IFERROR(B41/C41-1,"") -> -0.018987823 | F41: PDF p17
A42: 1至2年 | B42: 534561 | C42: 346183 | D42: =B42-C42 -> 188378 | E42: =IFERROR(B42/C42-1,"") -> 0.54415728 | F42: PDF p17
A43: 2至3年 | B43: 104513 | C43: 68344 | D43: =B43-C43 -> 36169 | E43: =IFERROR(B43/C43-1,"") -> 0.52921983 | F43: PDF p17
A44: 3年以上 | B44: 60453 | C44: 47790 | D44: =B44-C44 -> 12663 | E44: =IFERROR(B44/C44-1,"") -> 0.26497175 | F44: PDF p17
A45: 账龄合计 | B45: 6922203 | C45: 6805435 | D45: =B45-C45 -> 116768 | E45: =IFERROR(B45/C45-1,"") -> 0.017158051 | F45: PDF p17
B47: =B38/100000 -> 4.55124 | C47: =C38/100000 -> 3.4664 | D47: =D38/1000000 -> 0.108484 | E47: =E38/1000000 -> 3.1295869e-07 | F47: =F38/1000000 -> #VALUE!
B48: =B39/100000 -> 64.67079 | C48: =C39/100000 -> 64.58795 | D48: =D39/1000000 -> 0.008284 | E48: =E39/1000000 -> 1.2825922e-09 | F48: =F39/1000000 -> #VALUE!

Sheet 08_其他附注
A1: 其他财务附注与披露 | B1: 其他财务附注与披露 | C1: 其他财务附注与披露 | D1: 其他财务附注与披露 | E1: 其他财务附注与披露 | F1: 其他财务附注与披露 | G1: 其他财务附注与披露 | H1: 其他财务附注与披露
A2: 单位见各分区标题；披露值保留报告口径 | B2: 单位见各分区标题；披露值保留报告口径 | C2: 单位见各分区标题；披露值保留报告口径 | D2: 单位见各分区标题；披露值保留报告口径 | E2: 单位见各分区标题；披露值保留报告口径 | F2: 单位见各分区标题；披露值保留报告口径 | G2: 单位见各分区标题；披露值保留报告口径 | H2: 单位见各分区标题；披露值保留报告口径
A4: 其他收入及收益净额（人民币千元） | B4: 其他收入及收益净额（人民币千元） | C4: 其他收入及收益净额（人民币千元） | D4: 其他收入及收益净额（人民币千元） | E4: 其他收入及收益净额（人民币千元） | F4: 其他收入及收益净额（人民币千元）
A5: 项目 | B5: 2026H1 | C5: 2025H1 | D5: 变动额 | E5: 变动率 | F5: 来源
A7: 利息收入 | B7: 7311 | C7: 27805 | D7: =B7-C7 -> -20494 | E7: =IFERROR(B7/C7-1,"") -> -0.73706168 | F7: PDF p9
A8: 政府补助 | B8: 14196 | C8: 20155 | D8: =B8-C8 -> -5959 | E8: =IFERROR(B8/C8-1,"") -> -0.29565865 | F8: PDF p9
A9: FVTPL金融资产公允价值收益 | B9: 30423 | C9: 34508 | D9: =B9-C9 -> -4085 | E9: =IFERROR(B9/C9-1,"") -> -0.11837835 | F9: PDF p9
A10: 出售投资性物业收益 | B10: 12647 | C10: 11896 | D10: =B10-C10 -> 751 | E10: =IFERROR(B10/C10-1,"") -> 0.063130464 | F10: PDF p9
A11: 出售合营及联营企业收益 | B11: 421 | C11: 190 | D11: =B11-C11 -> 231 | E11: =IFERROR(B11/C11-1,"") -> 1.2157895 | F11: PDF p9
A12: 重新计量以往持有合营企业权益收益 | B12: 3933 | C12: 0 | D12: =B12-C12 -> 3933 | E12: =IFERROR(B12/C12-1,"") | F12: PDF p9
A13: 外汇差异净额 | B13: 3566 | C13: -3762 | D13: =B13-C13 -> 7328 | E13: =IFERROR(B13/C13-1,"") -> -1.9479001 | F13: PDF p9
A14: 其他非营业亏损 | B14: -16323 | C14: -27588 | D14: =B14-C14 -> 11265 | E14: =IFERROR(B14/C14-1,"") -> -0.40832971 | F14: PDF p9
A15: 合计 | B15: 56174 | C15: 63204 | D15: =B15-C15 -> -7030 | E15: =IFERROR(B15/C15-1,"") -> -0.11122714 | F15: PDF p9
A18: 税前利润附注（人民币千元） | B18: 税前利润附注（人民币千元） | C18: 税前利润附注（人民币千元） | D18: 税前利润附注（人民币千元） | E18: 税前利润附注（人民币千元） | F18: 税前利润附注（人民币千元）
A19: 项目 | B19: 2026H1 | C19: 2025H1 | D19: 变动额 | E19: 变动率 | F19: 来源
A21: 提供服务成本 | B21: 16530077 | C21: 15429723 | D21: =B21-C21 -> 1100354 | E21: =IFERROR(B21/C21-1,"") -> 0.071313918 | F21: PDF p10
A22: 出售存货成本 | B22: 163134 | C22: 214861 | D22: =B22-C22 -> -51727 | E22: =IFERROR(B22/C22-1,"") -> -0.24074634 | F22: PDF p10
A23: 折旧及摊销 | B23: 489609 | C23: 531358 | D23: =B23-C23 -> -41749 | E23: =IFERROR(B23/C23-1,"") -> -0.07857038 | F23: PDF p10
A24: 研发成本 | B24: 162132 | C24: 156931 | D24: =B24-C24 -> 5201 | E24: =IFERROR(B24/C24-1,"") -> 0.033141954 | F24: PDF p10
A25: 工资及薪金 | B25: 5142920 | C25: 4996248 | D25: =B25-C25 -> 146672 | E25: =IFERROR(B25/C25-1,"") -> 0.029356429 | F25: PDF p10
A26: 退休金、公积金、医保及其他社保 | B26: 1092082 | C26: 1008430 | D26: =B26-C26 -> 83652 | E26: =IFERROR(B26/C26-1,"") -> 0.082952709 | F26: PDF p10
A27: 员工福利开支合计 | B27: 6235002 | C27: 6004678 | D27: =B27-C27 -> 230324 | E27: =IFERROR(B27/C27-1,"") -> 0.038357427 | F27: PDF p10
A28: 贸易应收及应收保证金减值 | B28: 161220 | C28: 144683 | D28: =B28-C28 -> 16537 | E28: =IFERROR(B28/C28-1,"") -> 0.11429816 | F28: PDF p10
A29: 其他金融资产减值 | B29: 108722 | C29: 123339 | D29: =B29-C29 -> -14617 | E29: =IFERROR(B29/C29-1,"") -> -0.11851077 | F29: PDF p10
A30: 金融资产减值合计 | B30: 269942 | C30: 268022 | D30: =B30-C30 -> 1920 | E30: =IFERROR(B30/C30-1,"") -> 0.007163591 | F30: PDF p10
A33: 税项、股息及每股盈利 | B33: 税项、股息及每股盈利 | C33: 税项、股息及每股盈利 | D33: 税项、股息及每股盈利 | E33: 税项、股息及每股盈利 | F33: 税项、股息及每股盈利 | G33: 税项、股息及每股盈利 | H33: 税项、股息及每股盈利
A34: 项目 | B34: 2026H1 | C34: 2025H1 | D34: 单位 | E34: 变动额 | F34: 变动率 | G34: 来源 | H34: 备注
A36: 即期-中国利得税 | B36: 353498 | C36: 345142 | D36: 人民币千元 | E36: =IF(OR(B36="",C36=""),"",B36-C36) -> 8356 | F36: =IFERROR(B36/C36-1,"") -> 0.024210325 | G36: PDF p11
A37: 递延税项 | B37: -83340 | C37: -82312 | D37: 人民币千元 | E37: =IF(OR(B37="",C37=""),"",B37-C37) -> -1028 | F37: =IFERROR(B37/C37-1,"") -> 0.012489066 | G37: PDF p11
A38: 期内税项支出总额 | B38: 270158 | C38: 262830 | D38: 人民币千元 | E38: =IF(OR(B38="",C38=""),"",B38-C38) -> 7328 | F38: =IFERROR(B38/C38-1,"") -> 0.02788114 | G38: PDF p11
A39: 归母盈利（EPS分子） | B39: 781565 | C39: 791992 | D39: 人民币千元 | E39: =IF(OR(B39="",C39=""),"",B39-C39) -> -10427 | F39: =IFERROR(B39/C39-1,"") -> -0.013165537 | G39: PDF p12
A40: 加权平均普通股数 | B40: 1153686554 | C40: 1156779915 | D40: 股 | E40: =IF(OR(B40="",C40=""),"",B40-C40) -> -3093361 | F40: =IFERROR(B40/C40-1,"") -> -0.0026741137 | G40: PDF p12 | H40: 已考虑库存股
A41: 每股基本及摊薄盈利 | B41: 0.68 | C41: 0.68 | D41: 人民币元 | E41: =IF(OR(B41="",C41=""),"",B41-C41) -> 0 | F41: =IFERROR(B41/C41-1,"") -> 0 | G41: PDF p12
A42: 2026年中期股息 | B42: 0.711 | D42: 人民币元/股 | E42: =IF(OR(B42="",C42=""),"",B42-C42) | F42: =IFERROR(B42/C42-1,"") | G42: PDF p11 | H42: 待股东会批准
A43: 2026年中期股息总额 | B43: 820000 | D43: 人民币千元 | E43: =IF(OR(B43="",C43=""),"",B43-C43) | F43: =IFERROR(B43/C43-1,"") | G43: PDF p11
A47: 无形资产变动（2026H1，人民币千元） | B47: 无形资产变动（2026H1，人民币千元） | C47: 无形资产变动（2026H1，人民币千元） | D47: 无形资产变动（2026H1，人民币千元） | E47: 无形资产变动（2026H1，人民币千元） | F47: 无形资产变动（2026H1，人民币千元）
A48: 项目 | B48: 客户关系 | C48: 商誉 | D48: 其他 | E48: 合计 | F48: 来源
A50: 2026年1月1日账面净值 | B50: 3397864 | C50: 3999890 | D50: 61091 | E50: 7458845 | F50: PDF p12
A51: 添置 | B51: 0 | C51: 0 | D51: 9178 | E51: 9178 | F51: PDF p12
A52: 收购附属公司 | B52: 40148 | C52: 0 | D52: 0 | E52: 40148 | F52: PDF p12
...

Sheet 09_校验
A1: 数据完整性与勾稽校验 | B1: 数据完整性与勾稽校验 | C1: 数据完整性与勾稽校验 | D1: 数据完整性与勾稽校验 | E1: 数据完整性与勾稽校验 | F1: 数据完整性与勾稽校验 | G1: 数据完整性与勾稽校验
A2: 一行一项断言；差异容差默认为0.5千元（比率为0.01%） | B2: 一行一项断言；差异容差默认为0.5千元（比率为0.01%） | C2: 一行一项断言；差异容差默认为0.5千元（比率为0.01%） | D2: 一行一项断言；差异容差默认为0.5千元（比率为0.01%） | E2: 一行一项断言；差异容差默认为0.5千元（比率为0.01%） | F2: 一行一项断言；差异容差默认为0.5千元（比率为0.01%） | G2: 一行一项断言；差异容差默认为0.5千元（比率为0.01%） | H2: 一行一项断言；差异容差默认为0.5千元（比率为0.01%）
A4: 模型状态 | B4: =IF(COUNTIF(F7:F20,"FAIL")=0,"PASS","FAIL") -> PASS
A6: 校验项 | B6: Actual | C6: Expected | D6: Difference | E6: Tolerance | F6: Status | G6: Notes
A7: 收入：利润表=分业务合计 | B7: ='01_利润表'!B8 -> 19112370 | C7: ='04_收入与毛利'!B19 -> 19112370 | D7: =B7-C7 -> 0 | E7: 0.5 | F7: =IF(ABS(D7)<=E7,"PASS","FAIL") -> PASS
A8: 毛利：利润表=分业务合计 | B8: ='01_利润表'!B11 -> 2419159 | C8: ='04_收入与毛利'!G19 -> 2419159 | D8: =B8-C8 -> 0 | E8: 0.5 | F8: =IF(ABS(D8)<=E8,"PASS","FAIL") -> PASS
A9: 毛利=收入+销售成本 | B9: ='01_利润表'!B11 -> 2419159 | C9: ='01_利润表'!B8+'01_利润表'!B9 -> 2419159 | D9: =B9-C9 -> 0 | E9: 0.5 | F9: =IF(ABS(D9)<=E9,"PASS","FAIL") -> PASS
A10: 期内利润=归母+少数股东 | B10: ='01_利润表'!B20 -> 820008 | C10: ='01_利润表'!B22+'01_利润表'!B23 -> 820008 | D10: =B10-C10 -> 0 | E10: 0.5 | F10: =IF(ABS(D10)<=E10,"PASS","FAIL") -> PASS
A11: 全面收益=期内利润+其他全面收益 | B11: ='03_全面收益'!B11 -> 586533 | C11: ='03_全面收益'!B7+'03_全面收益'!B10 -> 586533 | D11: =B11-C11 -> 0 | E11: 0.5 | F11: =IF(ABS(D11)<=E11,"PASS","FAIL") -> PASS
A12: 全面收益=归属合计 | B12: ='03_全面收益'!B11 -> 586533 | C12: ='03_全面收益'!B14 -> 586533 | D12: =B12-C12 -> 0 | E12: 0.5 | F12: =IF(ABS(D12)<=E12,"PASS","FAIL") -> PASS
A13: 资产合计=流动+非流动 | B13: ='02_资产负债表'!B25 -> 36467827 | C13: ='02_资产负债表'!B16+'02_资产负债表'!B24 -> 36467827 | D13: =B13-C13 -> 0 | E13: 0.5 | F13: =IF(ABS(D13)<=E13,"PASS","FAIL") -> PASS
A14: 资产=负债+权益 | B14: ='02_资产负债表'!B25 -> 36467827 | C14: ='02_资产负债表'!B32+'02_资产负债表'!B40+'02_资产负债表'!B47 -> 36467827 | D14: =B14-C14 -> 0 | E14: 0.5 | F14: =IF(ABS(D14)<=E14,"PASS","FAIL") -> PASS
A15: 流动资产净额=流动资产-流动负债 | B15: ='02_资产负债表'!B33 -> 1301153 | C15: ='02_资产负债表'!B24-'02_资产负债表'!B32 -> 1301153 | D15: =B15-C15 -> 0 | E15: 0.5 | F15: =IF(ABS(D15)<=E15,"PASS","FAIL") -> PASS
A16: 应收账龄合计=应收净额 | B16: ='07_营运资本'!B22 -> 7002298 | C16: ='07_营运资本'!B12 -> 7002298 | D16: =B16-C16 -> 0 | E16: 0.5 | F16: =IF(ABS(D16)<=E16,"PASS","FAIL") -> PASS
A17: 应付账龄合计=应付合计 | B17: ='07_营运资本'!B45 -> 6922203 | C17: ='07_营运资本'!B40 -> 6922203 | D17: =B17-C17 -> 0 | E17: 0.5 | F17: =IF(ABS(D17)<=E17,"PASS","FAIL") -> PASS
A18: 无形资产变动合计=期末净值 | B18: ='08_其他附注'!E54 -> 7204951 | C18: =SUM('08_其他附注'!E50:E53) -> 7204951 | D18: =B18-C18 -> 0 | E18: 0.5 | F18: =IF(ABS(D18)<=E18,"PASS","FAIL") -> PASS
A19: 剔除开发商核心净利润桥接 | B19: ='05_核心利润'!B33 -> 1099269 | C19: ='05_核心利润'!B29+'05_核心利润'!B30+'05_核心利润'!B31+'05_核心利润'!B32 -> 1099269 | D19: =B19-C19 -> 0 | E19: 0.5 | F19: =IF(ABS(D19)<=E19,"PASS","FAIL") -> PASS
A20: 货币资金=现金+受限存款+定期存款 | B20: ='00_摘要'!B16 -> 10366500 | C20: =('02_资产负债表'!B21+'02_资产负债表'!B22+'02_资产负债表'!B23) -> 10366500 | D20: =B20-C20 -> 0 | E20: 1 | F20: =IF(ABS(D20)<=E20,"PASS","FAIL") -> PASS | G20: 摘要数据为百万元一位小数换算，容差1千元

Sheet 10_来源与口径
A1: 来源、口径与使用说明 | B1: 来源、口径与使用说明 | C1: 来源、口径与使用说明 | D1: 来源、口径与使用说明 | E1: 来源、口径与使用说明 | F1: 来源、口径与使用说明 | G1: 来源、口径与使用说明
A2: 本工作簿仅整理用户提供的业绩公告，未引入外部数据 | B2: 本工作簿仅整理用户提供的业绩公告，未引入外部数据 | C2: 本工作簿仅整理用户提供的业绩公告，未引入外部数据 | D2: 本工作簿仅整理用户提供的业绩公告，未引入外部数据 | E2: 本工作簿仅整理用户提供的业绩公告，未引入外部数据 | F2: 本工作簿仅整理用户提供的业绩公告，未引入外部数据 | G2: 本工作簿仅整理用户提供的业绩公告，未引入外部数据 | H2: 本工作簿仅整理用户提供的业绩公告，未引入外部数据
A5: 类型 | B5: 项目 | C5: 内容/口径 | D5: 期间/时点 | E5: 来源文件 | F5: 参考 | G5: 备注
A7: 主来源 | B7: 业绩公告 | C7: 万物云空间科技服务股份有限公司截至2026年6月30日止六个月未经审计中期业绩公告 | D7: 2026H1 | E7: 26H1-万物云业绩.pdf | F7: p1-p42 | G7: 公告创建日期2026-08-13
A8: 单位 | B8: 财务报表 | C8: 除特别标注外，为人民币千元 | D8: 2026H1/2025H1 | E8: 26H1-万物云业绩.pdf | F8: p3-p18
A9: 对比口径 | B9: 利润表/业务数据 | C9: 2026H1对2025H1 | D9: 6个月 | E9: 26H1-万物云业绩.pdf | F9: p3-p4,p9-p13,p26-p36
A10: 对比口径 | B10: 资产负债表 | C10: 2026-06-30对2025-12-31 | D10: 2026-06-30 | E10: 26H1-万物云业绩.pdf | F10: p5-p6,p14-p18
A11: 定义 | B11: 循环型业务 | C11: 住宅物业管理服务+物业及设施管理服务+BPaaS解决方案业务 | D11: 2026H1 | E11: 26H1-万物云业绩.pdf | F11: p2
A12: 定义 | B12: 剔除开发商业务影响 | C12: 剔除来自万科集团的持续关连交易及其他开发商的开发商增值服务影响 | D12: 2026H1 | E12: 26H1-万物云业绩.pdf | F12: p2
A13: 定义 | B13: 核心净利润 | C13: 归母利润剔除历史收购客户关系摊销、非经常性事项及相关所得税影响 | D13: 2026H1 | E13: 26H1-万物云业绩.pdf | F13: p2
A14: 限制 | B14: 现金流量表 | C14: 本公告财务报表摘要未提供完整合并现金流量表；仅整理管理层讨论中披露的现金流数据 | D14: 2026H1 | E14: 26H1-万物云业绩.pdf | F14: p36 | G14: 不应视为完整现金流量表
A15: 处理规则 | B15: 报告四舍五入值 | C15: 如公告只给出人民币百万元一位小数，则保留该精度，不反推成更精确数据 | D15: 2026H1 | E15: 26H1-万物云业绩.pdf | F15: p1,p28,p33-p38 | G15: 个别摘要指标换算为千元仅为汇总展示
A16: 使用说明 | B16: 颜色 | C16: 绿色字体=跨工作表公式；黑色=报告原数或本表公式；灰色=来源说明
A17: 使用说明 | B17: 更新 | C17: 若替换报告数据，应同步更新来源页码、期间和09_校验中的勾稽关系
